Workbook

Sheet Canada summary
A1: Canada: immediate expensing for machinery and buildings - weighted-average NPV and OECD rank, 2026-2030
A2: Values link to the per-year sheets. Rank change is positive when the reform improves Canada rank (current-law rank minus reform rank).
A4: Year | B4: Weighted avg (current law) | C4: Rank (current law) | D4: Weighted avg (reform) | E4: Rank (reform) | F4: Rank change (+ = better) | G4: Weighted-avg change
A5: =2026 -> 2026 | B5: ='2026'!F9 -> 0.85 | C5: ='2026'!G9 -> 5 | D5: ='2026'!K9 -> 1 | E5: ='2026'!L9 -> 1 | F5: =C5-E5 -> 4 | G5: =D5-B5 -> 0.15
A6: =2027 -> 2027 | B6: ='2027'!F9 -> 0.765 | C6: ='2027'!G9 -> 5 | D6: ='2027'!K9 -> 0.9149 | E6: ='2027'!L9 -> 5 | F6: =C6-E6 -> 0 | G6: =D6-B6 -> 0.1499
A7: =2028 -> 2028 | B7: ='2028'!F9 -> 0.765 | C7: ='2028'!G9 -> 5 | D7: ='2028'!K9 -> 0.9149 | E7: ='2028'!L9 -> 5 | F7: =C7-E7 -> 0 | G7: =D7-B7 -> 0.1499
A8: =2029 -> 2029 | B8: ='2029'!F9 -> 0.765 | C8: ='2029'!G9 -> 4 | D8: ='2029'!K9 -> 0.9149 | E8: ='2029'!L9 -> 4 | F8: =C8-E8 -> 0 | G8: =D8-B8 -> 0.1499
A9: =2030 -> 2030 | B9: ='2030'!F9 -> 0.7462 | C9: ='2030'!G9 -> 7 | D9: ='2030'!K9 -> 0.9149 | E9: ='2030'!L9 -> 4 | F9: =C9-E9 -> 3 | G9: =D9-B9 -> 0.1687

Sheet 2026
A1: Net Present Value of Capital Allowances, OECD Ranking 2026: current law vs. Canada immediate-expensing reform
A2: Weighted avg = weights (Notes) applied to asset NPVs (source: final-data/npv_all_years.csv). Reform sets Canada machinery and buildings to 1.0; intangibles unchanged. Ranks: RANK on weighted avg rounded to 4 dp, ties=min.
A4: Country | B4: ISO | C4: Buildings (current law) | D4: Machinery (current law) | E4: Intangibles (current law) | F4: Weighted avg (current law) | G4: Rank (current law) | H4: Buildings (reform) | I4: Machinery (reform) | J4: Intangibles (reform) | K4: Weighted avg (reform) | L4: Rank (reform)
A5: Estonia | B5: EST | C5: =1 -> 1 | D5: =1 -> 1 | E5: =1 -> 1 | F5: =ROUND(Notes!$B$4*D5+Notes!$B$5*C5+Notes!$B$6*E5,4) -> 1 | G5: =RANK(F5,F$5:F$42,0) -> 1 | H5: =C5 -> 1 | I5: =D5 -> 1 | J5: =E5 -> 1 | K5: =ROUND(Notes!$B$4*I5+Notes!$B$5*H5+Notes!$B$6*J5,4) -> 1 | L5: =RANK(K5,K$5:K$42,0) -> 1
A6: Latvia | B6: LVA | C6: =1 -> 1 | D6: =1 -> 1 | E6: =1 -> 1 | F6: =ROUND(Notes!$B$4*D6+Notes!$B$5*C6+Notes!$B$6*E6,4) -> 1 | G6: =RANK(F6,F$5:F$42,0) -> 1 | H6: =C6 -> 1 | I6: =D6 -> 1 | J6: =E6 -> 1 | K6: =ROUND(Notes!$B$4*I6+Notes!$B$5*H6+Notes!$B$6*J6,4) -> 1 | L6: =RANK(K6,K$5:K$42,0) -> 1
A7: United States | B7: USA | C7: =1 -> 1 | D7: =1 -> 1 | E7: =0.632751338890881 -> 0.63275134 | F7: =ROUND(Notes!$B$4*D7+Notes!$B$5*C7+Notes!$B$6*E7,4) -> 0.9452 | G7: =RANK(F7,F$5:F$42,0) -> 3 | H7: =C7 -> 1 | I7: =D7 -> 1 | J7: =E7 -> 0.63275134 | K7: =ROUND(Notes!$B$4*I7+Notes!$B$5*H7+Notes!$B$6*J7,4) -> 0.9452 | L7: =RANK(K7,K$5:K$42,0) -> 4
A8: Lithuania | B8: LTU | C8: =0.826923076923077 -> 0.82692308 | D8: =1 -> 1 | E8: =1 -> 1 | F8: =ROUND(Notes!$B$4*D8+Notes!$B$5*C8+Notes!$B$6*E8,4) -> 0.9288 | G8: =RANK(F8,F$5:F$42,0) -> 4 | H8: =C8 -> 0.82692308 | I8: =D8 -> 1 | J8: =E8 -> 1 | K8: =ROUND(Notes!$B$4*I8+Notes!$B$5*H8+Notes!$B$6*J8,4) -> 0.9288 | L8: =RANK(K8,K$5:K$42,0) -> 5
A9: Canada | B9: CAN | C9: =0.635714285714286 -> 0.63571429 | D9: =1 -> 1 | E9: =1 -> 1 | F9: =ROUND(Notes!$B$4*D9+Notes!$B$5*C9+Notes!$B$6*E9,4) -> 0.85 | G9: =RANK(F9,F$5:F$42,0) -> 5 | H9: =1 -> 1 | I9: =1 -> 1 | J9: =E9 -> 1 | K9: =ROUND(Notes!$B$4*I9+Notes!$B$5*H9+Notes!$B$6*J9,4) -> 1 | L9: =RANK(K9,K$5:K$42,0) -> 1
A10: Italy | B10: ITA | C10: =0.576669379707147 -> 0.57666938 | D10: =0.869865253929667 -> 0.86986525 | E10: =0.965116279069767 -> 0.96511628 | F10: =ROUND(Notes!$B$4*D10+Notes!$B$5*C10+Notes!$B$6*E10,4) -> 0.7634 | G10: =RANK(F10,F$5:F$42,0) -> 6 | H10: =C10 -> 0.57666938 | I10: =D10 -> 0.86986525 | J10: =E10 -> 0.96511628 | K10: =ROUND(Notes!$B$4*I10+Notes!$B$5*H10+Notes!$B$6*J10,4) -> 0.7634 | L10: =RANK(K10,K$5:K$42,0) -> 6
A11: Korea | B11: KOR | C11: =0.547953910556565 -> 0.54795391 | D11: =0.921720532319392 -> 0.92172053 | E11: =0.813463195231154 -> 0.8134632 | F11: =ROUND(Notes!$B$4*D11+Notes!$B$5*C11+Notes!$B$6*E11,4) -> 0.7517 | G11: =RANK(F11,F$5:F$42,0) -> 7 | H11: =C11 -> 0.54795391 | I11: =D11 -> 0.92172053 | J11: =E11 -> 0.8134632 | K11: =ROUND(Notes!$B$4*I11+Notes!$B$5*H11+Notes!$B$6*J11,4) -> 0.7517 | L11: =RANK(K11,K$5:K$42,0) -> 7
A12: Iceland | B12: ISL | C12: =0.602353618717047 -> 0.60235362 | D12: =0.86 -> 0.86 | E12: =0.812269350072009 -> 0.81226935 | F12: =ROUND(Notes!$B$4*D12+Notes!$B$5*C12+Notes!$B$6*E12,4) -> 0.7468 | G12: =RANK(F12,F$5:F$42,0) -> 8 | H12: =C12 -> 0.60235362 | I12: =D12 -> 0.86 | J12: =E12 -> 0.81226935 | K12: =ROUND(Notes!$B$4*I12+Notes!$B$5*H12+Notes!$B$6*J12,4) -> 0.7468 | L12: =RANK(K12,K$5:K$42,0) -> 8
A13: France | B13: FRA | C13: =0.547953910556565 -> 0.54795391 | D13: =0.880275603755891 -> 0.8802756 | E13: =0.869865253929667 -> 0.86986525 | F13: =ROUND(Notes!$B$4*D13+Notes!$B$5*C13+Notes!$B$6*E13,4) -> 0.7419 | G13: =RANK(F13,F$5:F$42,0) -> 9 | H13: =C13 -> 0.54795391 | I13: =D13 -> 0.8802756 | J13: =E13 -> 0.86986525 | K13: =ROUND(Notes!$B$4*I13+Notes!$B$5*H13+Notes!$B$6*J13,4) -> 0.7419 | L13: =RANK(K13,K$5:K$42,0) -> 9
A14: Switzerland | B14: CHE | C14: =0.554838709677419 -> 0.55483871 | D14: =0.86 -> 0.86 | E14: =0.905263157894737 -> 0.90526316 | F14: =ROUND(Notes!$B$4*D14+Notes!$B$5*C14+Notes!$B$6*E14,4) -> 0.7411 | G14: =RANK(F14,F$5:F$42,0) -> 10 | H14: =C14 -> 0.55483871 | I14: =D14 -> 0.86 | J14: =E14 -> 0.90526316 | K14: =ROUND(Notes!$B$4*I14+Notes!$B$5*H14+Notes!$B$6*J14,4) -> 0.7411 | L14: =RANK(K14,K$5:K$42,0) -> 10
A15: Slovakia | B15: SVK | C15: =0.547953910556565 -> 0.54795391 | D15: =0.873879108036537 -> 0.87387911 | E15: =0.869865253929667 -> 0.86986525 | F15: =ROUND(Notes!$B$4*D15+Notes!$B$5*C15+Notes!$B$6*E15,4) -> 0.7391 | G15: =RANK(F15,F$5:F$42,0) -> 11 | H15: =C15 -> 0.54795391 | I15: =D15 -> 0.87387911 | J15: =E15 -> 0.86986525 | K15: =ROUND(Notes!$B$4*I15+Notes!$B$5*H15+Notes!$B$6*J15,4) -> 0.7391 | L15: =RANK(K15,K$5:K$42,0) -> 11
A16: Belgium | B16: BEL | C16: =0.547953910556565 -> 0.54795391 | D16: =0.869865253929667 -> 0.86986525 | E16: =0.869865253929667 -> 0.86986525 | F16: =ROUND(Notes!$B$4*D16+Notes!$B$5*C16+Notes!$B$6*E16,4) -> 0.7373 | G16: =RANK(F16,F$5:F$42,0) -> 12 | H16: =C16 -> 0.54795391 | I16: =D16 -> 0.86986525 | J16: =E16 -> 0.86986525 | K16: =ROUND(Notes!$B$4*I16+Notes!$B$5*H16+Notes!$B$6*J16,4) -> 0.7373 | L16: =RANK(K16,K$5:K$42,0) -> 12
A17: Czech Republic | B17: CZE | C17: =0.543222830616488 -> 0.54322283 | D17: =0.873879108036537 -> 0.87387911 | E17: =0.841318847888109 -> 0.84131885 | F17: =ROUND(Notes!$B$4*D17+Notes!$B$5*C17+Notes!$B$6*E17,4) -> 0.7329 | G17: =RANK(F17,F$5:F$42,0) -> 13 | H17: =C17 -> 0.54322283 | I17: =D17 -> 0.87387911 | J17: =E17 -> 0.84131885 | K17: =ROUND(Notes!$B$4*I17+Notes!$B$5*H17+Notes!$B$6*J17,4) -> 0.7329 | L17: =RANK(K17,K$5:K$42,0) -> 13
A18: Mexico | B18: MEX | C18: =0.630382676079967 -> 0.63038268 | D18: =0.795219524916135 -> 0.79521952 | E18: =0.795219524916135 -> 0.79521952 | F18: =ROUND(Notes!$B$4*D18+Notes!$B$5*C18+Notes!$B$6*E18,4) -> 0.7274 | G18: =RANK(F18,F$5:F$42,0) -> 14 | H18: =C18 -> 0.63038268 | I18: =D18 -> 0.79521952 | J18: =E18 -> 0.79521952 | K18: =ROUND(Notes!$B$4*I18+Notes!$B$5*H18+Notes!$B$6*J18,4) -> 0.7274 | L18: =RANK(K18,K$5:K$42,0) -> 14
A19: United Kingdom | B19: GBR | C19: =0.391406012913837 -> 0.39140601 | D19: =1 -> 1 | E19: =0.826923076923077 -> 0.82692308 | F19: =ROUND(Notes!$B$4*D19+Notes!$B$5*C19+Notes!$B$6*E19,4) -> 0.7236 | G19: =RANK(F19,F$5:F$42,0) -> 15 | H19: =C19 -> 0.39140601 | I19: =D19 -> 1 | J19: =E19 -> 0.82692308 | K19: =ROUND(Notes!$B$4*I19+Notes!$B$5*H19+Notes!$B$6*J19,4) -> 0.7236 | L19: =RANK(K19,K$5:K$42,0) -> 15
A20: Israel | B20: ISR | C20: =0.478865241362287 -> 0.47886524 | D20: =0.901030024355631 -> 0.90103002 | E20: =0.835370889649727 -> 0.83537089 | F20: =ROUND(Notes!$B$4*D20+Notes!$B$5*C20+Notes!$B$6*E20,4) -> 0.7174 | G20: =RANK(F20,F$5:F$42,0) -> 16 | H20: =C20 -> 0.47886524 | I20: =D20 -> 0.90103002 | J20: =E20 -> 0.83537089 | K20: =ROUND(Notes!$B$4*I20+Notes!$B$5*H20+Notes!$B$6*J20,4) -> 0.7174 | L20: =RANK(K20,K$5:K$42,0) -> 16
A21: Luxembourg | B21: LUX | C21: =0.479318672008477 -> 0.47931867 | D21: =0.873417350634541 -> 0.87341735 | E21: =0.869865253929667 -> 0.86986525 | F21: =ROUND(Notes!$B$4*D21+Notes!$B$5*C21+Notes!$B$6*E21,4) -> 0.7107 | G21: =RANK(F21,F$5:F$42,0) -> 17 | H21: =C21 -> 0.47931867 | I21: =D21 -> 0.87341735 | J21: =E21 -> 0.86986525 | K21: =ROUND(Notes!$B$4*I21+Notes!$B$5*H21+Notes!$B$6*J21,4) -> 0.7107 | L21: =RANK(K21,K$5:K$42,0) -> 17
A22: Sweden | B22: SWE | C22: =0.479318672008477 -> 0.47931867 | D22: =0.86 -> 0.86 | E22: =0.86 -> 0.86 | F22: =ROUND(Notes!$B$4*D22+Notes!$B$5*C22+Notes!$B$6*E22,4) -> 0.7033 | G22: =RANK(F22,F$5:F$42,0) -> 18 | H22: =C22 -> 0.47931867 | I22: =D22 -> 0.86 | J22: =E22 -> 0.86 | K22: =ROUND(Notes!$B$4*I22+Notes!$B$5*H22+Notes!$B$6*J22,4) -> 0.7033 | L22: =RANK(K22,K$5:K$42,0) -> 18
A23: Portugal | B23: PRT | C23: =0.547953910556565 -> 0.54795391 | D23: =0.888411247396436 -> 0.88841125 | E23: =0.547953910556565 -> 0.54795391 | F23: =ROUND(Notes!$B$4*D23+Notes!$B$5*C23+Notes!$B$6*E23,4) -> 0.6975 | G23: =RANK(F23,F$5:F$42,0) -> 19 | H23: =C23 -> 0.54795391 | I23: =D23 -> 0.88841125 | J23: =E23 -> 0.54795391 | K23: =ROUND(Notes!$B$4*I23+Notes!$B$5*H23+Notes!$B$6*J23,4) -> 0.6975 | L23: =RANK(K23,K$5:K$42,0) -> 19
A24: Finland | B24: FIN | C24: =0.518965517241379 -> 0.51896552 | D24: =0.826923076923077 -> 0.82692308 | E24: =0.737888702767901 -> 0.7378887 | F24: =ROUND(Notes!$B$4*D24+Notes!$B$5*C24+Notes!$B$6*E24,4) -> 0.6869 | G24: =RANK(F24,F$5:F$42,0) -> 20 | H24: =C24 -> 0.51896552 | I24: =D24 -> 0.82692308 | J24: =E24 -> 0.7378887 | K24: =ROUND(Notes!$B$4*I24+Notes!$B$5*H24+Notes!$B$6*J24,4) -> 0.6869 | L24: =RANK(K24,K$5:K$42,0) -> 20
A25: Germany | B25: DEU | C25: =0.391406012913837 -> 0.39140601 | D25: =0.876514043282575 -> 0.87651404 | E25: =0.869865253929667 -> 0.86986525 | F25: =ROUND(Notes!$B$4*D25+Notes!$B$5*C25+Notes!$B$6*E25,4) -> 0.6758 | G25: =RANK(F25,F$5:F$42,0) -> 21 | H25: =C25 -> 0.39140601 | I25: =D25 -> 0.87651404 | J25: =E25 -> 0.86986525 | K25: =ROUND(Notes!$B$4*I25+Notes!$B$5*H25+Notes!$B$6*J25,4) -> 0.6758 | L25: =RANK(K25,K$5:K$42,0) -> 21
A26: Austria | B26: AUT | C26: =0.408845614108812 -> 0.40884561 | D26: =0.884365027341364 -> 0.88436503 | E26: =0.737888702767901 -> 0.7378887 | F26: =ROUND(Notes!$B$4*D26+Notes!$B$5*C26+Notes!$B$6*E26,4) -> 0.6668 | G26: =RANK(F26,F$5:F$42,0) -> 22 | H26: =C26 -> 0.40884561 | I26: =D26 -> 0.88436503 | J26: =E26 -> 0.7378887 | K26: =ROUND(Notes!$B$4*I26+Notes!$B$5*H26+Notes!$B$6*J26,4) -> 0.6668 | L26: =RANK(K26,K$5:K$42,0) -> 22
A27: Turkey | B27: TUR | C27: =0.431068736527055 -> 0.43106874 | D27: =0.864149148541634 -> 0.86414915 | E27: =0.69441435606903 -> 0.69441436 | F27: =ROUND(Notes!$B$4*D27+Notes!$B$5*C27+Notes!$B$6*E27,4) -> 0.6605 | G27: =RANK(F27,F$5:F$42,0) -> 23 | H27: =C27 -> 0.43106874 | I27: =D27 -> 0.86414915 | J27: =E27 -> 0.69441436 | K27: =ROUND(Notes!$B$4*I27+Notes!$B$5*H27+Notes!$B$6*J27,4) -> 0.6605 | L27: =RANK(K27,K$5:K$42,0) -> 23
A28: Slovenia | B28: SVN | C28: =0.391406012913837 -> 0.39140601 | D28: =0.869865253929667 -> 0.86986525 | E28: =0.737888702767901 -> 0.7378887 | F28: =ROUND(Notes!$B$4*D28+Notes!$B$5*C28+Notes!$B$6*E28,4) -> 0.6532 | G28: =RANK(F28,F$5:F$42,0) -> 24 | H28: =C28 -> 0.39140601 | I28: =D28 -> 0.86986525 | J28: =E28 -> 0.7378887 | K28: =ROUND(Notes!$B$4*I28+Notes!$B$5*H28+Notes!$B$6*J28,4) -> 0.6532 | L28: =RANK(K28,K$5:K$42,0) -> 24
A29: Australia | B29: AUS | C29: =0.479318672008477 -> 0.47931867 | D29: =0.851484971473245 -> 0.85148497 | E29: =0.547953910556565 -> 0.54795391 | F29: =ROUND(Notes!$B$4*D29+Notes!$B$5*C29+Notes!$B$6*E29,4) -> 0.653 | G29: =RANK(F29,F$5:F$42,0) -> 25 | H29: =C29 -> 0.47931867 | I29: =D29 -> 0.85148497 | J29: =E29 -> 0.54795391 | K29: =ROUND(Notes!$B$4*I29+Notes!$B$5*H29+Notes!$B$6*J29,4) -> 0.653 | L29: =RANK(K29,K$5:K$42,0) -> 25
A30: Denmark | B30: DNK | C30: =0.391406012913837 -> 0.39140601 | D30: =0.826923076923077 -> 0.82692308 | E30: =0.81340644290143 -> 0.81340644 | F30: =ROUND(Notes!$B$4*D30+Notes!$B$5*C30+Notes!$B$6*E30,4) -> 0.6456 | G30: =RANK(F30,F$5:F$42,0) -> 26 | H30: =C30 -> 0.39140601 | I30: =D30 -> 0.82692308 | J30: =E30 -> 0.81340644 | K30: =ROUND(Notes!$B$4*I30+Notes!$B$5*H30+Notes!$B$6*J30,4) -> 0.6456 | L30: =RANK(K30,K$5:K$42,0) -> 26
A31: Ireland | B31: IRL | C31: =0.479318672008477 -> 0.47931867 | D31: =0.787075165170195 -> 0.78707517 | E31: =0.646263719038607 -> 0.64626372 | F31: =ROUND(Notes!$B$4*D31+Notes!$B$5*C31+Notes!$B$6*E31,4) -> 0.6394 | G31: =RANK(F31,F$5:F$42,0) -> 27 | H31: =C31 -> 0.47931867 | I31: =D31 -> 0.78707517 | J31: =E31 -> 0.64626372 | K31: =ROUND(Notes!$B$4*I31+Notes!$B$5*H31+Notes!$B$6*J31,4) -> 0.6394 | L31: =RANK(K31,K$5:K$42,0) -> 27
A32: Greece | B32: GRC | C32: =0.479318672008477 -> 0.47931867 | D32: =0.737888702767901 -> 0.7378887 | E32: =0.737888702767901 -> 0.7378887 | F32: =ROUND(Notes!$B$4*D32+Notes!$B$5*C32+Notes!$B$6*E32,4) -> 0.6314 | G32: =RANK(F32,F$5:F$42,0) -> 28 | H32: =C32 -> 0.47931867 | I32: =D32 -> 0.7378887 | J32: =E32 -> 0.7378887 | K32: =ROUND(Notes!$B$4*I32+Notes!$B$5*H32+Notes!$B$6*J32,4) -> 0.6314 | L32: =RANK(K32,K$5:K$42,0) -> 28
A33: Netherlands | B33: NLD | C33: =0.338474732816403 -> 0.33847473 | D33: =0.813463195231154 -> 0.8134632 | E33: =0.869865253929667 -> 0.86986525 | F33: =ROUND(Notes!$B$4*D33+Notes!$B$5*C33+Notes!$B$6*E33,4) -> 0.6263 | G33: =RANK(F33,F$5:F$42,0) -> 29 | H33: =C33 -> 0.33847473 | I33: =D33 -> 0.8134632 | J33: =E33 -> 0.86986525 | K33: =ROUND(Notes!$B$4*I33+Notes!$B$5*H33+Notes!$B$6*J33,4) -> 0.6263 | L33: =RANK(K33,K$5:K$42,0) -> 29
A34: Spain | B34: ESP | C34: =0.391406012913837 -> 0.39140601 | D34: =0.778563038959402 -> 0.77856304 | E34: =0.737888702767901 -> 0.7378887 | F34: =ROUND(Notes!$B$4*D34+Notes!$B$5*C34+Notes!$B$6*E34,4) -> 0.6131 | G34: =RANK(F34,F$5:F$42,0) -> 30 | H34: =C34 -> 0.39140601 | I34: =D34 -> 0.77856304 | J34: =E34 -> 0.7378887 | K34: =ROUND(Notes!$B$4*I34+Notes!$B$5*H34+Notes!$B$6*J34,4) -> 0.6131 | L34: =RANK(K34,K$5:K$42,0) -> 30
A35: Japan | B35: JPN | C35: =0.278958448750364 -> 0.27895845 | D35: =0.859028659709284 -> 0.85902866 | E35: =0.787075165170195 -> 0.78707517 | F35: =ROUND(Notes!$B$4*D35+Notes!$B$5*C35+Notes!$B$6*E35,4) -> 0.6095 | G35: =RANK(F35,F$5:F$42,0) -> 31 | H35: =C35 -> 0.27895845 | I35: =D35 -> 0.85902866 | J35: =E35 -> 0.78707517 | K35: =ROUND(Notes!$B$4*I35+Notes!$B$5*H35+Notes!$B$6*J35,4) -> 0.6095 | L35: =RANK(K35,K$5:K$42,0) -> 31
A36: Norway | B36: NOR | C36: =0.373913043478261 -> 0.37391304 | D36: =0.781818181818182 -> 0.78181818 | E36: =0.737888702767901 -> 0.7378887 | F36: =ROUND(Notes!$B$4*D36+Notes!$B$5*C36+Notes!$B$6*E36,4) -> 0.6073 | G36: =RANK(F36,F$5:F$42,0) -> 32 | H36: =C36 -> 0.37391304 | I36: =D36 -> 0.78181818 | J36: =E36 -> 0.7378887 | K36: =ROUND(Notes!$B$4*I36+Notes!$B$5*H36+Notes!$B$6*J36,4) -> 0.6073 | L36: =RANK(K36,K$5:K$42,0) -> 32
A37: Poland | B37: POL | C37: =0.338474732816403 -> 0.33847473 | D37: =0.737888702767901 -> 0.7378887 | E37: =0.869865253929667 -> 0.86986525 | F37: =ROUND(Notes!$B$4*D37+Notes!$B$5*C37+Notes!$B$6*E37,4) -> 0.5932 | G37: =RANK(F37,F$5:F$42,0) -> 33 | H37: =C37 -> 0.33847473 | I37: =D37 -> 0.7378887 | J37: =E37 -> 0.86986525 | K37: =ROUND(Notes!$B$4*I37+Notes!$B$5*H37+Notes!$B$6*J37,4) -> 0.5932 | L37: =RANK(K37,K$5:K$42,0) -> 33
A38: Costa Rica | B38: CRI | C38: =0.278958448750364 -> 0.27895845 | D38: =0.822456690745778 -> 0.82245669 | E38: =0.737888702767901 -> 0.7378887 | F38: =ROUND(Notes!$B$4*D38+Notes!$B$5*C38+Notes!$B$6*E38,4) -> 0.5861 | G38: =RANK(F38,F$5:F$42,0) -> 34 | H38: =C38 -> 0.27895845 | I38: =D38 -> 0.82245669 | J38: =E38 -> 0.7378887 | K38: =ROUND(Notes!$B$4*I38+Notes!$B$5*H38+Notes!$B$6*J38,4) -> 0.5861 | L38: =RANK(K38,K$5:K$42,0) -> 34
A39: Hungary | B39: HUN | C39: =0.278958448750364 -> 0.27895845 | D39: =0.816200383417959 -> 0.81620038 | E39: =0.737888702767901 -> 0.7378887 | F39: =ROUND(Notes!$B$4*D39+Notes!$B$5*C39+Notes!$B$6*E39,4) -> 0.5834 | G39: =RANK(F39,F$5:F$42,0) -> 35 | H39: =C39 -> 0.27895845 | I39: =D39 -> 0.81620038 | J39: =E39 -> 0.7378887 | K39: =ROUND(Notes!$B$4*I39+Notes!$B$5*H39+Notes!$B$6*J39,4) -> 0.5834 | L39: =RANK(K39,K$5:K$42,0) -> 35
A40: Colombia | B40: COL | C40: =0.305956530933891 -> 0.30595653 | D40: =0.737888702767901 -> 0.7378887 | E40: =0.869865253929667 -> 0.86986525 | F40: =ROUND(Notes!$B$4*D40+Notes!$B$5*C40+Notes!$B$6*E40,4) -> 0.5798 | G40: =RANK(F40,F$5:F$42,0) -> 36 | H40: =C40 -> 0.30595653 | I40: =D40 -> 0.7378887 | J40: =E40 -> 0.86986525 | K40: =ROUND(Notes!$B$4*I40+Notes!$B$5*H40+Notes!$B$6*J40,4) -> 0.5798 | L40: =RANK(K40,K$5:K$42,0) -> 36
A41: New Zealand | B41: NZL | C41: =0.2 -> 0.2 | D41: =0.74468085106383 -> 0.74468085 | E41: =0.547953910556565 -> 0.54795391 | F41: =ROUND(Notes!$B$4*D41+Notes!$B$5*C41+Notes!$B$6*E41,4) -> 0.4911 | G41: =RANK(F41,F$5:F$42,0) -> 37 | H41: =C41 -> 0.2 | I41: =D41 -> 0.74468085 | J41: =E41 -> 0.54795391 | K41: =ROUND(Notes!$B$4*I41+Notes!$B$5*H41+Notes!$B$6*J41,4) -> 0.4911 | L41: =RANK(K41,K$5:K$42,0) -> 37
...

Sheet 2027
A1: Net Present Value of Capital Allowances, OECD Ranking 2027: current law vs. Canada immediate-expensing reform
A2: Weighted avg = weights (Notes) applied to asset NPVs (source: final-data/npv_all_years.csv). Reform sets Canada machinery and buildings to 1.0; intangibles unchanged. Ranks: RANK on weighted avg rounded to 4 dp, ties=min.
A4: Country | B4: ISO | C4: Buildings (current law) | D4: Machinery (current law) | E4: Intangibles (current law) | F4: Weighted avg (current law) | G4: Rank (current law) | H4: Buildings (reform) | I4: Machinery (reform) | J4: Intangibles (reform) | K4: Weighted avg (reform) | L4: Rank (reform)
A5: Estonia | B5: EST | C5: =1 -> 1 | D5: =1 -> 1 | E5: =1 -> 1 | F5: =ROUND(Notes!$B$4*D5+Notes!$B$5*C5+Notes!$B$6*E5,4) -> 1 | G5: =RANK(F5,F$5:F$42,0) -> 1 | H5: =C5 -> 1 | I5: =D5 -> 1 | J5: =E5 -> 1 | K5: =ROUND(Notes!$B$4*I5+Notes!$B$5*H5+Notes!$B$6*J5,4) -> 1 | L5: =RANK(K5,K$5:K$42,0) -> 1
A6: Latvia | B6: LVA | C6: =1 -> 1 | D6: =1 -> 1 | E6: =1 -> 1 | F6: =ROUND(Notes!$B$4*D6+Notes!$B$5*C6+Notes!$B$6*E6,4) -> 1 | G6: =RANK(F6,F$5:F$42,0) -> 1 | H6: =C6 -> 1 | I6: =D6 -> 1 | J6: =E6 -> 1 | K6: =ROUND(Notes!$B$4*I6+Notes!$B$5*H6+Notes!$B$6*J6,4) -> 1 | L6: =RANK(K6,K$5:K$42,0) -> 1
A7: United States | B7: USA | C7: =1 -> 1 | D7: =1 -> 1 | E7: =0.632751338890881 -> 0.63275134 | F7: =ROUND(Notes!$B$4*D7+Notes!$B$5*C7+Notes!$B$6*E7,4) -> 0.9452 | G7: =RANK(F7,F$5:F$42,0) -> 3 | H7: =C7 -> 1 | I7: =D7 -> 1 | J7: =E7 -> 0.63275134 | K7: =ROUND(Notes!$B$4*I7+Notes!$B$5*H7+Notes!$B$6*J7,4) -> 0.9452 | L7: =RANK(K7,K$5:K$42,0) -> 3
A8: Lithuania | B8: LTU | C8: =0.826923076923077 -> 0.82692308 | D8: =1 -> 1 | E8: =1 -> 1 | F8: =ROUND(Notes!$B$4*D8+Notes!$B$5*C8+Notes!$B$6*E8,4) -> 0.9288 | G8: =RANK(F8,F$5:F$42,0) -> 4 | H8: =C8 -> 0.82692308 | I8: =D8 -> 1 | J8: =E8 -> 1 | K8: =ROUND(Notes!$B$4*I8+Notes!$B$5*H8+Notes!$B$6*J8,4) -> 0.9288 | L8: =RANK(K8,K$5:K$42,0) -> 4
A9: Canada | B9: CAN | C9: =0.635714285714286 -> 0.63571429 | D9: =1 -> 1 | E9: =0.43 -> 0.43 | F9: =ROUND(Notes!$B$4*D9+Notes!$B$5*C9+Notes!$B$6*E9,4) -> 0.765 | G9: =RANK(F9,F$5:F$42,0) -> 5 | H9: =1 -> 1 | I9: =1 -> 1 | J9: =E9 -> 0.43 | K9: =ROUND(Notes!$B$4*I9+Notes!$B$5*H9+Notes!$B$6*J9,4) -> 0.9149 | L9: =RANK(K9,K$5:K$42,0) -> 5
A10: Italy | B10: ITA | C10: =0.576669379707147 -> 0.57666938 | D10: =0.869865253929667 -> 0.86986525 | E10: =0.965116279069767 -> 0.96511628 | F10: =ROUND(Notes!$B$4*D10+Notes!$B$5*C10+Notes!$B$6*E10,4) -> 0.7634 | G10: =RANK(F10,F$5:F$42,0) -> 6 | H10: =C10 -> 0.57666938 | I10: =D10 -> 0.86986525 | J10: =E10 -> 0.96511628 | K10: =ROUND(Notes!$B$4*I10+Notes!$B$5*H10+Notes!$B$6*J10,4) -> 0.7634 | L10: =RANK(K10,K$5:K$42,0) -> 6
A11: Korea | B11: KOR | C11: =0.547953910556565 -> 0.54795391 | D11: =0.921720532319392 -> 0.92172053 | E11: =0.813463195231154 -> 0.8134632 | F11: =ROUND(Notes!$B$4*D11+Notes!$B$5*C11+Notes!$B$6*E11,4) -> 0.7517 | G11: =RANK(F11,F$5:F$42,0) -> 7 | H11: =C11 -> 0.54795391 | I11: =D11 -> 0.92172053 | J11: =E11 -> 0.8134632 | K11: =ROUND(Notes!$B$4*I11+Notes!$B$5*H11+Notes!$B$6*J11,4) -> 0.7517 | L11: =RANK(K11,K$5:K$42,0) -> 7
A12: Iceland | B12: ISL | C12: =0.602353618717047 -> 0.60235362 | D12: =0.86 -> 0.86 | E12: =0.812269350072009 -> 0.81226935 | F12: =ROUND(Notes!$B$4*D12+Notes!$B$5*C12+Notes!$B$6*E12,4) -> 0.7468 | G12: =RANK(F12,F$5:F$42,0) -> 8 | H12: =C12 -> 0.60235362 | I12: =D12 -> 0.86 | J12: =E12 -> 0.81226935 | K12: =ROUND(Notes!$B$4*I12+Notes!$B$5*H12+Notes!$B$6*J12,4) -> 0.7468 | L12: =RANK(K12,K$5:K$42,0) -> 8
A13: France | B13: FRA | C13: =0.547953910556565 -> 0.54795391 | D13: =0.880275603755891 -> 0.8802756 | E13: =0.869865253929667 -> 0.86986525 | F13: =ROUND(Notes!$B$4*D13+Notes!$B$5*C13+Notes!$B$6*E13,4) -> 0.7419 | G13: =RANK(F13,F$5:F$42,0) -> 9 | H13: =C13 -> 0.54795391 | I13: =D13 -> 0.8802756 | J13: =E13 -> 0.86986525 | K13: =ROUND(Notes!$B$4*I13+Notes!$B$5*H13+Notes!$B$6*J13,4) -> 0.7419 | L13: =RANK(K13,K$5:K$42,0) -> 9
A14: Switzerland | B14: CHE | C14: =0.554838709677419 -> 0.55483871 | D14: =0.86 -> 0.86 | E14: =0.905263157894737 -> 0.90526316 | F14: =ROUND(Notes!$B$4*D14+Notes!$B$5*C14+Notes!$B$6*E14,4) -> 0.7411 | G14: =RANK(F14,F$5:F$42,0) -> 10 | H14: =C14 -> 0.55483871 | I14: =D14 -> 0.86 | J14: =E14 -> 0.90526316 | K14: =ROUND(Notes!$B$4*I14+Notes!$B$5*H14+Notes!$B$6*J14,4) -> 0.7411 | L14: =RANK(K14,K$5:K$42,0) -> 10
A15: Slovakia | B15: SVK | C15: =0.547953910556565 -> 0.54795391 | D15: =0.873879108036537 -> 0.87387911 | E15: =0.869865253929667 -> 0.86986525 | F15: =ROUND(Notes!$B$4*D15+Notes!$B$5*C15+Notes!$B$6*E15,4) -> 0.7391 | G15: =RANK(F15,F$5:F$42,0) -> 11 | H15: =C15 -> 0.54795391 | I15: =D15 -> 0.87387911 | J15: =E15 -> 0.86986525 | K15: =ROUND(Notes!$B$4*I15+Notes!$B$5*H15+Notes!$B$6*J15,4) -> 0.7391 | L15: =RANK(K15,K$5:K$42,0) -> 11
A16: Belgium | B16: BEL | C16: =0.547953910556565 -> 0.54795391 | D16: =0.869865253929667 -> 0.86986525 | E16: =0.869865253929667 -> 0.86986525 | F16: =ROUND(Notes!$B$4*D16+Notes!$B$5*C16+Notes!$B$6*E16,4) -> 0.7373 | G16: =RANK(F16,F$5:F$42,0) -> 12 | H16: =C16 -> 0.54795391 | I16: =D16 -> 0.86986525 | J16: =E16 -> 0.86986525 | K16: =ROUND(Notes!$B$4*I16+Notes!$B$5*H16+Notes!$B$6*J16,4) -> 0.7373 | L16: =RANK(K16,K$5:K$42,0) -> 12
A17: Czech Republic | B17: CZE | C17: =0.543222830616488 -> 0.54322283 | D17: =0.873879108036537 -> 0.87387911 | E17: =0.841318847888109 -> 0.84131885 | F17: =ROUND(Notes!$B$4*D17+Notes!$B$5*C17+Notes!$B$6*E17,4) -> 0.7329 | G17: =RANK(F17,F$5:F$42,0) -> 13 | H17: =C17 -> 0.54322283 | I17: =D17 -> 0.87387911 | J17: =E17 -> 0.84131885 | K17: =ROUND(Notes!$B$4*I17+Notes!$B$5*H17+Notes!$B$6*J17,4) -> 0.7329 | L17: =RANK(K17,K$5:K$42,0) -> 13
A18: Mexico | B18: MEX | C18: =0.630382676079967 -> 0.63038268 | D18: =0.795219524916135 -> 0.79521952 | E18: =0.795219524916135 -> 0.79521952 | F18: =ROUND(Notes!$B$4*D18+Notes!$B$5*C18+Notes!$B$6*E18,4) -> 0.7274 | G18: =RANK(F18,F$5:F$42,0) -> 14 | H18: =C18 -> 0.63038268 | I18: =D18 -> 0.79521952 | J18: =E18 -> 0.79521952 | K18: =ROUND(Notes!$B$4*I18+Notes!$B$5*H18+Notes!$B$6*J18,4) -> 0.7274 | L18: =RANK(K18,K$5:K$42,0) -> 14
A19: United Kingdom | B19: GBR | C19: =0.391406012913837 -> 0.39140601 | D19: =1 -> 1 | E19: =0.826923076923077 -> 0.82692308 | F19: =ROUND(Notes!$B$4*D19+Notes!$B$5*C19+Notes!$B$6*E19,4) -> 0.7236 | G19: =RANK(F19,F$5:F$42,0) -> 15 | H19: =C19 -> 0.39140601 | I19: =D19 -> 1 | J19: =E19 -> 0.82692308 | K19: =ROUND(Notes!$B$4*I19+Notes!$B$5*H19+Notes!$B$6*J19,4) -> 0.7236 | L19: =RANK(K19,K$5:K$42,0) -> 15
A20: Israel | B20: ISR | C20: =0.478865241362287 -> 0.47886524 | D20: =0.901030024355631 -> 0.90103002 | E20: =0.835370889649727 -> 0.83537089 | F20: =ROUND(Notes!$B$4*D20+Notes!$B$5*C20+Notes!$B$6*E20,4) -> 0.7174 | G20: =RANK(F20,F$5:F$42,0) -> 16 | H20: =C20 -> 0.47886524 | I20: =D20 -> 0.90103002 | J20: =E20 -> 0.83537089 | K20: =ROUND(Notes!$B$4*I20+Notes!$B$5*H20+Notes!$B$6*J20,4) -> 0.7174 | L20: =RANK(K20,K$5:K$42,0) -> 16
A21: Luxembourg | B21: LUX | C21: =0.479318672008477 -> 0.47931867 | D21: =0.873417350634541 -> 0.87341735 | E21: =0.869865253929667 -> 0.86986525 | F21: =ROUND(Notes!$B$4*D21+Notes!$B$5*C21+Notes!$B$6*E21,4) -> 0.7107 | G21: =RANK(F21,F$5:F$42,0) -> 17 | H21: =C21 -> 0.47931867 | I21: =D21 -> 0.87341735 | J21: =E21 -> 0.86986525 | K21: =ROUND(Notes!$B$4*I21+Notes!$B$5*H21+Notes!$B$6*J21,4) -> 0.7107 | L21: =RANK(K21,K$5:K$42,0) -> 17
A22: Sweden | B22: SWE | C22: =0.479318672008477 -> 0.47931867 | D22: =0.86 -> 0.86 | E22: =0.86 -> 0.86 | F22: =ROUND(Notes!$B$4*D22+Notes!$B$5*C22+Notes!$B$6*E22,4) -> 0.7033 | G22: =RANK(F22,F$5:F$42,0) -> 18 | H22: =C22 -> 0.47931867 | I22: =D22 -> 0.86 | J22: =E22 -> 0.86 | K22: =ROUND(Notes!$B$4*I22+Notes!$B$5*H22+Notes!$B$6*J22,4) -> 0.7033 | L22: =RANK(K22,K$5:K$42,0) -> 18
A23: Portugal | B23: PRT | C23: =0.547953910556565 -> 0.54795391 | D23: =0.888411247396436 -> 0.88841125 | E23: =0.547953910556565 -> 0.54795391 | F23: =ROUND(Notes!$B$4*D23+Notes!$B$5*C23+Notes!$B$6*E23,4) -> 0.6975 | G23: =RANK(F23,F$5:F$42,0) -> 19 | H23: =C23 -> 0.54795391 | I23: =D23 -> 0.88841125 | J23: =E23 -> 0.54795391 | K23: =ROUND(Notes!$B$4*I23+Notes!$B$5*H23+Notes!$B$6*J23,4) -> 0.6975 | L23: =RANK(K23,K$5:K$42,0) -> 19
A24: Finland | B24: FIN | C24: =0.518965517241379 -> 0.51896552 | D24: =0.826923076923077 -> 0.82692308 | E24: =0.737888702767901 -> 0.7378887 | F24: =ROUND(Notes!$B$4*D24+Notes!$B$5*C24+Notes!$B$6*E24,4) -> 0.6869 | G24: =RANK(F24,F$5:F$42,0) -> 20 | H24: =C24 -> 0.51896552 | I24: =D24 -> 0.82692308 | J24: =E24 -> 0.7378887 | K24: =ROUND(Notes!$B$4*I24+Notes!$B$5*H24+Notes!$B$6*J24,4) -> 0.6869 | L24: =RANK(K24,K$5:K$42,0) -> 20
A25: Germany | B25: DEU | C25: =0.391406012913837 -> 0.39140601 | D25: =0.876514043282575 -> 0.87651404 | E25: =0.869865253929667 -> 0.86986525 | F25: =ROUND(Notes!$B$4*D25+Notes!$B$5*C25+Notes!$B$6*E25,4) -> 0.6758 | G25: =RANK(F25,F$5:F$42,0) -> 21 | H25: =C25 -> 0.39140601 | I25: =D25 -> 0.87651404 | J25: =E25 -> 0.86986525 | K25: =ROUND(Notes!$B$4*I25+Notes!$B$5*H25+Notes!$B$6*J25,4) -> 0.6758 | L25: =RANK(K25,K$5:K$42,0) -> 21
A26: Austria | B26: AUT | C26: =0.408845614108812 -> 0.40884561 | D26: =0.884365027341364 -> 0.88436503 | E26: =0.737888702767901 -> 0.7378887 | F26: =ROUND(Notes!$B$4*D26+Notes!$B$5*C26+Notes!$B$6*E26,4) -> 0.6668 | G26: =RANK(F26,F$5:F$42,0) -> 22 | H26: =C26 -> 0.40884561 | I26: =D26 -> 0.88436503 | J26: =E26 -> 0.7378887 | K26: =ROUND(Notes!$B$4*I26+Notes!$B$5*H26+Notes!$B$6*J26,4) -> 0.6668 | L26: =RANK(K26,K$5:K$42,0) -> 22
A27: Turkey | B27: TUR | C27: =0.431068736527055 -> 0.43106874 | D27: =0.864149148541634 -> 0.86414915 | E27: =0.69441435606903 -> 0.69441436 | F27: =ROUND(Notes!$B$4*D27+Notes!$B$5*C27+Notes!$B$6*E27,4) -> 0.6605 | G27: =RANK(F27,F$5:F$42,0) -> 23 | H27: =C27 -> 0.43106874 | I27: =D27 -> 0.86414915 | J27: =E27 -> 0.69441436 | K27: =ROUND(Notes!$B$4*I27+Notes!$B$5*H27+Notes!$B$6*J27,4) -> 0.6605 | L27: =RANK(K27,K$5:K$42,0) -> 23
A28: Slovenia | B28: SVN | C28: =0.391406012913837 -> 0.39140601 | D28: =0.869865253929667 -> 0.86986525 | E28: =0.737888702767901 -> 0.7378887 | F28: =ROUND(Notes!$B$4*D28+Notes!$B$5*C28+Notes!$B$6*E28,4) -> 0.6532 | G28: =RANK(F28,F$5:F$42,0) -> 24 | H28: =C28 -> 0.39140601 | I28: =D28 -> 0.86986525 | J28: =E28 -> 0.7378887 | K28: =ROUND(Notes!$B$4*I28+Notes!$B$5*H28+Notes!$B$6*J28,4) -> 0.6532 | L28: =RANK(K28,K$5:K$42,0) -> 24
A29: Australia | B29: AUS | C29: =0.479318672008477 -> 0.47931867 | D29: =0.851484971473245 -> 0.85148497 | E29: =0.547953910556565 -> 0.54795391 | F29: =ROUND(Notes!$B$4*D29+Notes!$B$5*C29+Notes!$B$6*E29,4) -> 0.653 | G29: =RANK(F29,F$5:F$42,0) -> 25 | H29: =C29 -> 0.47931867 | I29: =D29 -> 0.85148497 | J29: =E29 -> 0.54795391 | K29: =ROUND(Notes!$B$4*I29+Notes!$B$5*H29+Notes!$B$6*J29,4) -> 0.653 | L29: =RANK(K29,K$5:K$42,0) -> 25
A30: Denmark | B30: DNK | C30: =0.391406012913837 -> 0.39140601 | D30: =0.826923076923077 -> 0.82692308 | E30: =0.81340644290143 -> 0.81340644 | F30: =ROUND(Notes!$B$4*D30+Notes!$B$5*C30+Notes!$B$6*E30,4) -> 0.6456 | G30: =RANK(F30,F$5:F$42,0) -> 26 | H30: =C30 -> 0.39140601 | I30: =D30 -> 0.82692308 | J30: =E30 -> 0.81340644 | K30: =ROUND(Notes!$B$4*I30+Notes!$B$5*H30+Notes!$B$6*J30,4) -> 0.6456 | L30: =RANK(K30,K$5:K$42,0) -> 26
A31: Ireland | B31: IRL | C31: =0.479318672008477 -> 0.47931867 | D31: =0.787075165170195 -> 0.78707517 | E31: =0.646263719038607 -> 0.64626372 | F31: =ROUND(Notes!$B$4*D31+Notes!$B$5*C31+Notes!$B$6*E31,4) -> 0.6394 | G31: =RANK(F31,F$5:F$42,0) -> 27 | H31: =C31 -> 0.47931867 | I31: =D31 -> 0.78707517 | J31: =E31 -> 0.64626372 | K31: =ROUND(Notes!$B$4*I31+Notes!$B$5*H31+Notes!$B$6*J31,4) -> 0.6394 | L31: =RANK(K31,K$5:K$42,0) -> 27
A32: Greece | B32: GRC | C32: =0.479318672008477 -> 0.47931867 | D32: =0.737888702767901 -> 0.7378887 | E32: =0.737888702767901 -> 0.7378887 | F32: =ROUND(Notes!$B$4*D32+Notes!$B$5*C32+Notes!$B$6*E32,4) -> 0.6314 | G32: =RANK(F32,F$5:F$42,0) -> 28 | H32: =C32 -> 0.47931867 | I32: =D32 -> 0.7378887 | J32: =E32 -> 0.7378887 | K32: =ROUND(Notes!$B$4*I32+Notes!$B$5*H32+Notes!$B$6*J32,4) -> 0.6314 | L32: =RANK(K32,K$5:K$42,0) -> 28
A33: Netherlands | B33: NLD | C33: =0.338474732816403 -> 0.33847473 | D33: =0.813463195231154 -> 0.8134632 | E33: =0.869865253929667 -> 0.86986525 | F33: =ROUND(Notes!$B$4*D33+Notes!$B$5*C33+Notes!$B$6*E33,4) -> 0.6263 | G33: =RANK(F33,F$5:F$42,0) -> 29 | H33: =C33 -> 0.33847473 | I33: =D33 -> 0.8134632 | J33: =E33 -> 0.86986525 | K33: =ROUND(Notes!$B$4*I33+Notes!$B$5*H33+Notes!$B$6*J33,4) -> 0.6263 | L33: =RANK(K33,K$5:K$42,0) -> 29
A34: Spain | B34: ESP | C34: =0.391406012913837 -> 0.39140601 | D34: =0.778563038959402 -> 0.77856304 | E34: =0.737888702767901 -> 0.7378887 | F34: =ROUND(Notes!$B$4*D34+Notes!$B$5*C34+Notes!$B$6*E34,4) -> 0.6131 | G34: =RANK(F34,F$5:F$42,0) -> 30 | H34: =C34 -> 0.39140601 | I34: =D34 -> 0.77856304 | J34: =E34 -> 0.7378887 | K34: =ROUND(Notes!$B$4*I34+Notes!$B$5*H34+Notes!$B$6*J34,4) -> 0.6131 | L34: =RANK(K34,K$5:K$42,0) -> 30
A35: Japan | B35: JPN | C35: =0.278958448750364 -> 0.27895845 | D35: =0.859028659709284 -> 0.85902866 | E35: =0.787075165170195 -> 0.78707517 | F35: =ROUND(Notes!$B$4*D35+Notes!$B$5*C35+Notes!$B$6*E35,4) -> 0.6095 | G35: =RANK(F35,F$5:F$42,0) -> 31 | H35: =C35 -> 0.27895845 | I35: =D35 -> 0.85902866 | J35: =E35 -> 0.78707517 | K35: =ROUND(Notes!$B$4*I35+Notes!$B$5*H35+Notes!$B$6*J35,4) -> 0.6095 | L35: =RANK(K35,K$5:K$42,0) -> 31
A36: Norway | B36: NOR | C36: =0.373913043478261 -> 0.37391304 | D36: =0.781818181818182 -> 0.78181818 | E36: =0.737888702767901 -> 0.7378887 | F36: =ROUND(Notes!$B$4*D36+Notes!$B$5*C36+Notes!$B$6*E36,4) -> 0.6073 | G36: =RANK(F36,F$5:F$42,0) -> 32 | H36: =C36 -> 0.37391304 | I36: =D36 -> 0.78181818 | J36: =E36 -> 0.7378887 | K36: =ROUND(Notes!$B$4*I36+Notes!$B$5*H36+Notes!$B$6*J36,4) -> 0.6073 | L36: =RANK(K36,K$5:K$42,0) -> 32
A37: Poland | B37: POL | C37: =0.338474732816403 -> 0.33847473 | D37: =0.737888702767901 -> 0.7378887 | E37: =0.869865253929667 -> 0.86986525 | F37: =ROUND(Notes!$B$4*D37+Notes!$B$5*C37+Notes!$B$6*E37,4) -> 0.5932 | G37: =RANK(F37,F$5:F$42,0) -> 33 | H37: =C37 -> 0.33847473 | I37: =D37 -> 0.7378887 | J37: =E37 -> 0.86986525 | K37: =ROUND(Notes!$B$4*I37+Notes!$B$5*H37+Notes!$B$6*J37,4) -> 0.5932 | L37: =RANK(K37,K$5:K$42,0) -> 33
A38: Costa Rica | B38: CRI | C38: =0.278958448750364 -> 0.27895845 | D38: =0.822456690745778 -> 0.82245669 | E38: =0.737888702767901 -> 0.7378887 | F38: =ROUND(Notes!$B$4*D38+Notes!$B$5*C38+Notes!$B$6*E38,4) -> 0.5861 | G38: =RANK(F38,F$5:F$42,0) -> 34 | H38: =C38 -> 0.27895845 | I38: =D38 -> 0.82245669 | J38: =E38 -> 0.7378887 | K38: =ROUND(Notes!$B$4*I38+Notes!$B$5*H38+Notes!$B$6*J38,4) -> 0.5861 | L38: =RANK(K38,K$5:K$42,0) -> 34
A39: Hungary | B39: HUN | C39: =0.278958448750364 -> 0.27895845 | D39: =0.816200383417959 -> 0.81620038 | E39: =0.737888702767901 -> 0.7378887 | F39: =ROUND(Notes!$B$4*D39+Notes!$B$5*C39+Notes!$B$6*E39,4) -> 0.5834 | G39: =RANK(F39,F$5:F$42,0) -> 35 | H39: =C39 -> 0.27895845 | I39: =D39 -> 0.81620038 | J39: =E39 -> 0.7378887 | K39: =ROUND(Notes!$B$4*I39+Notes!$B$5*H39+Notes!$B$6*J39,4) -> 0.5834 | L39: =RANK(K39,K$5:K$42,0) -> 35
A40: Colombia | B40: COL | C40: =0.305956530933891 -> 0.30595653 | D40: =0.737888702767901 -> 0.7378887 | E40: =0.869865253929667 -> 0.86986525 | F40: =ROUND(Notes!$B$4*D40+Notes!$B$5*C40+Notes!$B$6*E40,4) -> 0.5798 | G40: =RANK(F40,F$5:F$42,0) -> 36 | H40: =C40 -> 0.30595653 | I40: =D40 -> 0.7378887 | J40: =E40 -> 0.86986525 | K40: =ROUND(Notes!$B$4*I40+Notes!$B$5*H40+Notes!$B$6*J40,4) -> 0.5798 | L40: =RANK(K40,K$5:K$42,0) -> 36
A41: New Zealand | B41: NZL | C41: =0.2 -> 0.2 | D41: =0.74468085106383 -> 0.74468085 | E41: =0.547953910556565 -> 0.54795391 | F41: =ROUND(Notes!$B$4*D41+Notes!$B$5*C41+Notes!$B$6*E41,4) -> 0.4911 | G41: =RANK(F41,F$5:F$42,0) -> 37 | H41: =C41 -> 0.2 | I41: =D41 -> 0.74468085 | J41: =E41 -> 0.54795391 | K41: =ROUND(Notes!$B$4*I41+Notes!$B$5*H41+Notes!$B$6*J41,4) -> 0.4911 | L41: =RANK(K41,K$5:K$42,0) -> 37
...

Sheet 2028
A1: Net Present Value of Capital Allowances, OECD Ranking 2028: current law vs. Canada immediate-expensing reform
A2: Weighted avg = weights (Notes) applied to asset NPVs (source: final-data/npv_all_years.csv). Reform sets Canada machinery and buildings to 1.0; intangibles unchanged. Ranks: RANK on weighted avg rounded to 4 dp, ties=min.
A4: Country | B4: ISO | C4: Buildings (current law) | D4: Machinery (current law) | E4: Intangibles (current law) | F4: Weighted avg (current law) | G4: Rank (current law) | H4: Buildings (reform) | I4: Machinery (reform) | J4: Intangibles (reform) | K4: Weighted avg (reform) | L4: Rank (reform)
A5: Estonia | B5: EST | C5: =1 -> 1 | D5: =1 -> 1 | E5: =1 -> 1 | F5: =ROUND(Notes!$B$4*D5+Notes!$B$5*C5+Notes!$B$6*E5,4) -> 1 | G5: =RANK(F5,F$5:F$42,0) -> 1 | H5: =C5 -> 1 | I5: =D5 -> 1 | J5: =E5 -> 1 | K5: =ROUND(Notes!$B$4*I5+Notes!$B$5*H5+Notes!$B$6*J5,4) -> 1 | L5: =RANK(K5,K$5:K$42,0) -> 1
A6: Latvia | B6: LVA | C6: =1 -> 1 | D6: =1 -> 1 | E6: =1 -> 1 | F6: =ROUND(Notes!$B$4*D6+Notes!$B$5*C6+Notes!$B$6*E6,4) -> 1 | G6: =RANK(F6,F$5:F$42,0) -> 1 | H6: =C6 -> 1 | I6: =D6 -> 1 | J6: =E6 -> 1 | K6: =ROUND(Notes!$B$4*I6+Notes!$B$5*H6+Notes!$B$6*J6,4) -> 1 | L6: =RANK(K6,K$5:K$42,0) -> 1
A7: United States | B7: USA | C7: =1 -> 1 | D7: =1 -> 1 | E7: =0.632751338890881 -> 0.63275134 | F7: =ROUND(Notes!$B$4*D7+Notes!$B$5*C7+Notes!$B$6*E7,4) -> 0.9452 | G7: =RANK(F7,F$5:F$42,0) -> 3 | H7: =C7 -> 1 | I7: =D7 -> 1 | J7: =E7 -> 0.63275134 | K7: =ROUND(Notes!$B$4*I7+Notes!$B$5*H7+Notes!$B$6*J7,4) -> 0.9452 | L7: =RANK(K7,K$5:K$42,0) -> 3
A8: Lithuania | B8: LTU | C8: =0.826923076923077 -> 0.82692308 | D8: =1 -> 1 | E8: =1 -> 1 | F8: =ROUND(Notes!$B$4*D8+Notes!$B$5*C8+Notes!$B$6*E8,4) -> 0.9288 | G8: =RANK(F8,F$5:F$42,0) -> 4 | H8: =C8 -> 0.82692308 | I8: =D8 -> 1 | J8: =E8 -> 1 | K8: =ROUND(Notes!$B$4*I8+Notes!$B$5*H8+Notes!$B$6*J8,4) -> 0.9288 | L8: =RANK(K8,K$5:K$42,0) -> 4
A9: Canada | B9: CAN | C9: =0.635714285714286 -> 0.63571429 | D9: =1 -> 1 | E9: =0.43 -> 0.43 | F9: =ROUND(Notes!$B$4*D9+Notes!$B$5*C9+Notes!$B$6*E9,4) -> 0.765 | G9: =RANK(F9,F$5:F$42,0) -> 5 | H9: =1 -> 1 | I9: =1 -> 1 | J9: =E9 -> 0.43 | K9: =ROUND(Notes!$B$4*I9+Notes!$B$5*H9+Notes!$B$6*J9,4) -> 0.9149 | L9: =RANK(K9,K$5:K$42,0) -> 5
A10: Italy | B10: ITA | C10: =0.576669379707147 -> 0.57666938 | D10: =0.869865253929667 -> 0.86986525 | E10: =0.965116279069767 -> 0.96511628 | F10: =ROUND(Notes!$B$4*D10+Notes!$B$5*C10+Notes!$B$6*E10,4) -> 0.7634 | G10: =RANK(F10,F$5:F$42,0) -> 6 | H10: =C10 -> 0.57666938 | I10: =D10 -> 0.86986525 | J10: =E10 -> 0.96511628 | K10: =ROUND(Notes!$B$4*I10+Notes!$B$5*H10+Notes!$B$6*J10,4) -> 0.7634 | L10: =RANK(K10,K$5:K$42,0) -> 6
A11: Korea | B11: KOR | C11: =0.547953910556565 -> 0.54795391 | D11: =0.921720532319392 -> 0.92172053 | E11: =0.813463195231154 -> 0.8134632 | F11: =ROUND(Notes!$B$4*D11+Notes!$B$5*C11+Notes!$B$6*E11,4) -> 0.7517 | G11: =RANK(F11,F$5:F$42,0) -> 7 | H11: =C11 -> 0.54795391 | I11: =D11 -> 0.92172053 | J11: =E11 -> 0.8134632 | K11: =ROUND(Notes!$B$4*I11+Notes!$B$5*H11+Notes!$B$6*J11,4) -> 0.7517 | L11: =RANK(K11,K$5:K$42,0) -> 7
A12: Iceland | B12: ISL | C12: =0.602353618717047 -> 0.60235362 | D12: =0.86 -> 0.86 | E12: =0.812269350072009 -> 0.81226935 | F12: =ROUND(Notes!$B$4*D12+Notes!$B$5*C12+Notes!$B$6*E12,4) -> 0.7468 | G12: =RANK(F12,F$5:F$42,0) -> 8 | H12: =C12 -> 0.60235362 | I12: =D12 -> 0.86 | J12: =E12 -> 0.81226935 | K12: =ROUND(Notes!$B$4*I12+Notes!$B$5*H12+Notes!$B$6*J12,4) -> 0.7468 | L12: =RANK(K12,K$5:K$42,0) -> 8
A13: France | B13: FRA | C13: =0.547953910556565 -> 0.54795391 | D13: =0.880275603755891 -> 0.8802756 | E13: =0.869865253929667 -> 0.86986525 | F13: =ROUND(Notes!$B$4*D13+Notes!$B$5*C13+Notes!$B$6*E13,4) -> 0.7419 | G13: =RANK(F13,F$5:F$42,0) -> 9 | H13: =C13 -> 0.54795391 | I13: =D13 -> 0.8802756 | J13: =E13 -> 0.86986525 | K13: =ROUND(Notes!$B$4*I13+Notes!$B$5*H13+Notes!$B$6*J13,4) -> 0.7419 | L13: =RANK(K13,K$5:K$42,0) -> 9
A14: Switzerland | B14: CHE | C14: =0.554838709677419 -> 0.55483871 | D14: =0.86 -> 0.86 | E14: =0.905263157894737 -> 0.90526316 | F14: =ROUND(Notes!$B$4*D14+Notes!$B$5*C14+Notes!$B$6*E14,4) -> 0.7411 | G14: =RANK(F14,F$5:F$42,0) -> 10 | H14: =C14 -> 0.55483871 | I14: =D14 -> 0.86 | J14: =E14 -> 0.90526316 | K14: =ROUND(Notes!$B$4*I14+Notes!$B$5*H14+Notes!$B$6*J14,4) -> 0.7411 | L14: =RANK(K14,K$5:K$42,0) -> 10
A15: Slovakia | B15: SVK | C15: =0.547953910556565 -> 0.54795391 | D15: =0.873879108036537 -> 0.87387911 | E15: =0.869865253929667 -> 0.86986525 | F15: =ROUND(Notes!$B$4*D15+Notes!$B$5*C15+Notes!$B$6*E15,4) -> 0.7391 | G15: =RANK(F15,F$5:F$42,0) -> 11 | H15: =C15 -> 0.54795391 | I15: =D15 -> 0.87387911 | J15: =E15 -> 0.86986525 | K15: =ROUND(Notes!$B$4*I15+Notes!$B$5*H15+Notes!$B$6*J15,4) -> 0.7391 | L15: =RANK(K15,K$5:K$42,0) -> 11
A16: Belgium | B16: BEL | C16: =0.547953910556565 -> 0.54795391 | D16: =0.869865253929667 -> 0.86986525 | E16: =0.869865253929667 -> 0.86986525 | F16: =ROUND(Notes!$B$4*D16+Notes!$B$5*C16+Notes!$B$6*E16,4) -> 0.7373 | G16: =RANK(F16,F$5:F$42,0) -> 12 | H16: =C16 -> 0.54795391 | I16: =D16 -> 0.86986525 | J16: =E16 -> 0.86986525 | K16: =ROUND(Notes!$B$4*I16+Notes!$B$5*H16+Notes!$B$6*J16,4) -> 0.7373 | L16: =RANK(K16,K$5:K$42,0) -> 12
A17: Czech Republic | B17: CZE | C17: =0.543222830616488 -> 0.54322283 | D17: =0.873879108036537 -> 0.87387911 | E17: =0.841318847888109 -> 0.84131885 | F17: =ROUND(Notes!$B$4*D17+Notes!$B$5*C17+Notes!$B$6*E17,4) -> 0.7329 | G17: =RANK(F17,F$5:F$42,0) -> 13 | H17: =C17 -> 0.54322283 | I17: =D17 -> 0.87387911 | J17: =E17 -> 0.84131885 | K17: =ROUND(Notes!$B$4*I17+Notes!$B$5*H17+Notes!$B$6*J17,4) -> 0.7329 | L17: =RANK(K17,K$5:K$42,0) -> 13
A18: Mexico | B18: MEX | C18: =0.630382676079967 -> 0.63038268 | D18: =0.795219524916135 -> 0.79521952 | E18: =0.795219524916135 -> 0.79521952 | F18: =ROUND(Notes!$B$4*D18+Notes!$B$5*C18+Notes!$B$6*E18,4) -> 0.7274 | G18: =RANK(F18,F$5:F$42,0) -> 14 | H18: =C18 -> 0.63038268 | I18: =D18 -> 0.79521952 | J18: =E18 -> 0.79521952 | K18: =ROUND(Notes!$B$4*I18+Notes!$B$5*H18+Notes!$B$6*J18,4) -> 0.7274 | L18: =RANK(K18,K$5:K$42,0) -> 14
A19: United Kingdom | B19: GBR | C19: =0.391406012913837 -> 0.39140601 | D19: =1 -> 1 | E19: =0.826923076923077 -> 0.82692308 | F19: =ROUND(Notes!$B$4*D19+Notes!$B$5*C19+Notes!$B$6*E19,4) -> 0.7236 | G19: =RANK(F19,F$5:F$42,0) -> 15 | H19: =C19 -> 0.39140601 | I19: =D19 -> 1 | J19: =E19 -> 0.82692308 | K19: =ROUND(Notes!$B$4*I19+Notes!$B$5*H19+Notes!$B$6*J19,4) -> 0.7236 | L19: =RANK(K19,K$5:K$42,0) -> 15
A20: Israel | B20: ISR | C20: =0.478865241362287 -> 0.47886524 | D20: =0.901030024355631 -> 0.90103002 | E20: =0.835370889649727 -> 0.83537089 | F20: =ROUND(Notes!$B$4*D20+Notes!$B$5*C20+Notes!$B$6*E20,4) -> 0.7174 | G20: =RANK(F20,F$5:F$42,0) -> 16 | H20: =C20 -> 0.47886524 | I20: =D20 -> 0.90103002 | J20: =E20 -> 0.83537089 | K20: =ROUND(Notes!$B$4*I20+Notes!$B$5*H20+Notes!$B$6*J20,4) -> 0.7174 | L20: =RANK(K20,K$5:K$42,0) -> 16
A21: Luxembourg | B21: LUX | C21: =0.479318672008477 -> 0.47931867 | D21: =0.873417350634541 -> 0.87341735 | E21: =0.869865253929667 -> 0.86986525 | F21: =ROUND(Notes!$B$4*D21+Notes!$B$5*C21+Notes!$B$6*E21,4) -> 0.7107 | G21: =RANK(F21,F$5:F$42,0) -> 17 | H21: =C21 -> 0.47931867 | I21: =D21 -> 0.87341735 | J21: =E21 -> 0.86986525 | K21: =ROUND(Notes!$B$4*I21+Notes!$B$5*H21+Notes!$B$6*J21,4) -> 0.7107 | L21: =RANK(K21,K$5:K$42,0) -> 17
A22: Sweden | B22: SWE | C22: =0.479318672008477 -> 0.47931867 | D22: =0.86 -> 0.86 | E22: =0.86 -> 0.86 | F22: =ROUND(Notes!$B$4*D22+Notes!$B$5*C22+Notes!$B$6*E22,4) -> 0.7033 | G22: =RANK(F22,F$5:F$42,0) -> 18 | H22: =C22 -> 0.47931867 | I22: =D22 -> 0.86 | J22: =E22 -> 0.86 | K22: =ROUND(Notes!$B$4*I22+Notes!$B$5*H22+Notes!$B$6*J22,4) -> 0.7033 | L22: =RANK(K22,K$5:K$42,0) -> 18
A23: Portugal | B23: PRT | C23: =0.547953910556565 -> 0.54795391 | D23: =0.888411247396436 -> 0.88841125 | E23: =0.547953910556565 -> 0.54795391 | F23: =ROUND(Notes!$B$4*D23+Notes!$B$5*C23+Notes!$B$6*E23,4) -> 0.6975 | G23: =RANK(F23,F$5:F$42,0) -> 19 | H23: =C23 -> 0.54795391 | I23: =D23 -> 0.88841125 | J23: =E23 -> 0.54795391 | K23: =ROUND(Notes!$B$4*I23+Notes!$B$5*H23+Notes!$B$6*J23,4) -> 0.6975 | L23: =RANK(K23,K$5:K$42,0) -> 19
A24: Finland | B24: FIN | C24: =0.518965517241379 -> 0.51896552 | D24: =0.826923076923077 -> 0.82692308 | E24: =0.737888702767901 -> 0.7378887 | F24: =ROUND(Notes!$B$4*D24+Notes!$B$5*C24+Notes!$B$6*E24,4) -> 0.6869 | G24: =RANK(F24,F$5:F$42,0) -> 20 | H24: =C24 -> 0.51896552 | I24: =D24 -> 0.82692308 | J24: =E24 -> 0.7378887 | K24: =ROUND(Notes!$B$4*I24+Notes!$B$5*H24+Notes!$B$6*J24,4) -> 0.6869 | L24: =RANK(K24,K$5:K$42,0) -> 20
A25: Germany | B25: DEU | C25: =0.391406012913837 -> 0.39140601 | D25: =0.737888702767901 -> 0.7378887 | E25: =0.869865253929667 -> 0.86986525 | F25: =ROUND(Notes!$B$4*D25+Notes!$B$5*C25+Notes!$B$6*E25,4) -> 0.6149 | G25: =RANK(F25,F$5:F$42,0) -> 29 | H25: =C25 -> 0.39140601 | I25: =D25 -> 0.7378887 | J25: =E25 -> 0.86986525 | K25: =ROUND(Notes!$B$4*I25+Notes!$B$5*H25+Notes!$B$6*J25,4) -> 0.6149 | L25: =RANK(K25,K$5:K$42,0) -> 29
A26: Austria | B26: AUT | C26: =0.408845614108812 -> 0.40884561 | D26: =0.884365027341364 -> 0.88436503 | E26: =0.737888702767901 -> 0.7378887 | F26: =ROUND(Notes!$B$4*D26+Notes!$B$5*C26+Notes!$B$6*E26,4) -> 0.6668 | G26: =RANK(F26,F$5:F$42,0) -> 21 | H26: =C26 -> 0.40884561 | I26: =D26 -> 0.88436503 | J26: =E26 -> 0.7378887 | K26: =ROUND(Notes!$B$4*I26+Notes!$B$5*H26+Notes!$B$6*J26,4) -> 0.6668 | L26: =RANK(K26,K$5:K$42,0) -> 21
A27: Turkey | B27: TUR | C27: =0.431068736527055 -> 0.43106874 | D27: =0.864149148541634 -> 0.86414915 | E27: =0.69441435606903 -> 0.69441436 | F27: =ROUND(Notes!$B$4*D27+Notes!$B$5*C27+Notes!$B$6*E27,4) -> 0.6605 | G27: =RANK(F27,F$5:F$42,0) -> 22 | H27: =C27 -> 0.43106874 | I27: =D27 -> 0.86414915 | J27: =E27 -> 0.69441436 | K27: =ROUND(Notes!$B$4*I27+Notes!$B$5*H27+Notes!$B$6*J27,4) -> 0.6605 | L27: =RANK(K27,K$5:K$42,0) -> 22
A28: Slovenia | B28: SVN | C28: =0.391406012913837 -> 0.39140601 | D28: =0.869865253929667 -> 0.86986525 | E28: =0.737888702767901 -> 0.7378887 | F28: =ROUND(Notes!$B$4*D28+Notes!$B$5*C28+Notes!$B$6*E28,4) -> 0.6532 | G28: =RANK(F28,F$5:F$42,0) -> 23 | H28: =C28 -> 0.39140601 | I28: =D28 -> 0.86986525 | J28: =E28 -> 0.7378887 | K28: =ROUND(Notes!$B$4*I28+Notes!$B$5*H28+Notes!$B$6*J28,4) -> 0.6532 | L28: =RANK(K28,K$5:K$42,0) -> 23
A29: Australia | B29: AUS | C29: =0.479318672008477 -> 0.47931867 | D29: =0.851484971473245 -> 0.85148497 | E29: =0.547953910556565 -> 0.54795391 | F29: =ROUND(Notes!$B$4*D29+Notes!$B$5*C29+Notes!$B$6*E29,4) -> 0.653 | G29: =RANK(F29,F$5:F$42,0) -> 24 | H29: =C29 -> 0.47931867 | I29: =D29 -> 0.85148497 | J29: =E29 -> 0.54795391 | K29: =ROUND(Notes!$B$4*I29+Notes!$B$5*H29+Notes!$B$6*J29,4) -> 0.653 | L29: =RANK(K29,K$5:K$42,0) -> 24
A30: Denmark | B30: DNK | C30: =0.391406012913837 -> 0.39140601 | D30: =0.826923076923077 -> 0.82692308 | E30: =0.81340644290143 -> 0.81340644 | F30: =ROUND(Notes!$B$4*D30+Notes!$B$5*C30+Notes!$B$6*E30,4) -> 0.6456 | G30: =RANK(F30,F$5:F$42,0) -> 25 | H30: =C30 -> 0.39140601 | I30: =D30 -> 0.82692308 | J30: =E30 -> 0.81340644 | K30: =ROUND(Notes!$B$4*I30+Notes!$B$5*H30+Notes!$B$6*J30,4) -> 0.6456 | L30: =RANK(K30,K$5:K$42,0) -> 25
A31: Ireland | B31: IRL | C31: =0.479318672008477 -> 0.47931867 | D31: =0.787075165170195 -> 0.78707517 | E31: =0.646263719038607 -> 0.64626372 | F31: =ROUND(Notes!$B$4*D31+Notes!$B$5*C31+Notes!$B$6*E31,4) -> 0.6394 | G31: =RANK(F31,F$5:F$42,0) -> 26 | H31: =C31 -> 0.47931867 | I31: =D31 -> 0.78707517 | J31: =E31 -> 0.64626372 | K31: =ROUND(Notes!$B$4*I31+Notes!$B$5*H31+Notes!$B$6*J31,4) -> 0.6394 | L31: =RANK(K31,K$5:K$42,0) -> 26
A32: Greece | B32: GRC | C32: =0.479318672008477 -> 0.47931867 | D32: =0.737888702767901 -> 0.7378887 | E32: =0.737888702767901 -> 0.7378887 | F32: =ROUND(Notes!$B$4*D32+Notes!$B$5*C32+Notes!$B$6*E32,4) -> 0.6314 | G32: =RANK(F32,F$5:F$42,0) -> 27 | H32: =C32 -> 0.47931867 | I32: =D32 -> 0.7378887 | J32: =E32 -> 0.7378887 | K32: =ROUND(Notes!$B$4*I32+Notes!$B$5*H32+Notes!$B$6*J32,4) -> 0.6314 | L32: =RANK(K32,K$5:K$42,0) -> 27
A33: Netherlands | B33: NLD | C33: =0.338474732816403 -> 0.33847473 | D33: =0.813463195231154 -> 0.8134632 | E33: =0.869865253929667 -> 0.86986525 | F33: =ROUND(Notes!$B$4*D33+Notes!$B$5*C33+Notes!$B$6*E33,4) -> 0.6263 | G33: =RANK(F33,F$5:F$42,0) -> 28 | H33: =C33 -> 0.33847473 | I33: =D33 -> 0.8134632 | J33: =E33 -> 0.86986525 | K33: =ROUND(Notes!$B$4*I33+Notes!$B$5*H33+Notes!$B$6*J33,4) -> 0.6263 | L33: =RANK(K33,K$5:K$42,0) -> 28
A34: Spain | B34: ESP | C34: =0.391406012913837 -> 0.39140601 | D34: =0.778563038959402 -> 0.77856304 | E34: =0.737888702767901 -> 0.7378887 | F34: =ROUND(Notes!$B$4*D34+Notes!$B$5*C34+Notes!$B$6*E34,4) -> 0.6131 | G34: =RANK(F34,F$5:F$42,0) -> 30 | H34: =C34 -> 0.39140601 | I34: =D34 -> 0.77856304 | J34: =E34 -> 0.7378887 | K34: =ROUND(Notes!$B$4*I34+Notes!$B$5*H34+Notes!$B$6*J34,4) -> 0.6131 | L34: =RANK(K34,K$5:K$42,0) -> 30
A35: Japan | B35: JPN | C35: =0.278958448750364 -> 0.27895845 | D35: =0.859028659709284 -> 0.85902866 | E35: =0.787075165170195 -> 0.78707517 | F35: =ROUND(Notes!$B$4*D35+Notes!$B$5*C35+Notes!$B$6*E35,4) -> 0.6095 | G35: =RANK(F35,F$5:F$42,0) -> 31 | H35: =C35 -> 0.27895845 | I35: =D35 -> 0.85902866 | J35: =E35 -> 0.78707517 | K35: =ROUND(Notes!$B$4*I35+Notes!$B$5*H35+Notes!$B$6*J35,4) -> 0.6095 | L35: =RANK(K35,K$5:K$42,0) -> 31
A36: Norway | B36: NOR | C36: =0.373913043478261 -> 0.37391304 | D36: =0.781818181818182 -> 0.78181818 | E36: =0.737888702767901 -> 0.7378887 | F36: =ROUND(Notes!$B$4*D36+Notes!$B$5*C36+Notes!$B$6*E36,4) -> 0.6073 | G36: =RANK(F36,F$5:F$42,0) -> 32 | H36: =C36 -> 0.37391304 | I36: =D36 -> 0.78181818 | J36: =E36 -> 0.7378887 | K36: =ROUND(Notes!$B$4*I36+Notes!$B$5*H36+Notes!$B$6*J36,4) -> 0.6073 | L36: =RANK(K36,K$5:K$42,0) -> 32
A37: Poland | B37: POL | C37: =0.338474732816403 -> 0.33847473 | D37: =0.737888702767901 -> 0.7378887 | E37: =0.869865253929667 -> 0.86986525 | F37: =ROUND(Notes!$B$4*D37+Notes!$B$5*C37+Notes!$B$6*E37,4) -> 0.5932 | G37: =RANK(F37,F$5:F$42,0) -> 33 | H37: =C37 -> 0.33847473 | I37: =D37 -> 0.7378887 | J37: =E37 -> 0.86986525 | K37: =ROUND(Notes!$B$4*I37+Notes!$B$5*H37+Notes!$B$6*J37,4) -> 0.5932 | L37: =RANK(K37,K$5:K$42,0) -> 33
A38: Costa Rica | B38: CRI | C38: =0.278958448750364 -> 0.27895845 | D38: =0.822456690745778 -> 0.82245669 | E38: =0.737888702767901 -> 0.7378887 | F38: =ROUND(Notes!$B$4*D38+Notes!$B$5*C38+Notes!$B$6*E38,4) -> 0.5861 | G38: =RANK(F38,F$5:F$42,0) -> 34 | H38: =C38 -> 0.27895845 | I38: =D38 -> 0.82245669 | J38: =E38 -> 0.7378887 | K38: =ROUND(Notes!$B$4*I38+Notes!$B$5*H38+Notes!$B$6*J38,4) -> 0.5861 | L38: =RANK(K38,K$5:K$42,0) -> 34
A39: Hungary | B39: HUN | C39: =0.278958448750364 -> 0.27895845 | D39: =0.816200383417959 -> 0.81620038 | E39: =0.737888702767901 -> 0.7378887 | F39: =ROUND(Notes!$B$4*D39+Notes!$B$5*C39+Notes!$B$6*E39,4) -> 0.5834 | G39: =RANK(F39,F$5:F$42,0) -> 35 | H39: =C39 -> 0.27895845 | I39: =D39 -> 0.81620038 | J39: =E39 -> 0.7378887 | K39: =ROUND(Notes!$B$4*I39+Notes!$B$5*H39+Notes!$B$6*J39,4) -> 0.5834 | L39: =RANK(K39,K$5:K$42,0) -> 35
A40: Colombia | B40: COL | C40: =0.305956530933891 -> 0.30595653 | D40: =0.737888702767901 -> 0.7378887 | E40: =0.869865253929667 -> 0.86986525 | F40: =ROUND(Notes!$B$4*D40+Notes!$B$5*C40+Notes!$B$6*E40,4) -> 0.5798 | G40: =RANK(F40,F$5:F$42,0) -> 36 | H40: =C40 -> 0.30595653 | I40: =D40 -> 0.7378887 | J40: =E40 -> 0.86986525 | K40: =ROUND(Notes!$B$4*I40+Notes!$B$5*H40+Notes!$B$6*J40,4) -> 0.5798 | L40: =RANK(K40,K$5:K$42,0) -> 36
A41: New Zealand | B41: NZL | C41: =0.2 -> 0.2 | D41: =0.74468085106383 -> 0.74468085 | E41: =0.547953910556565 -> 0.54795391 | F41: =ROUND(Notes!$B$4*D41+Notes!$B$5*C41+Notes!$B$6*E41,4) -> 0.4911 | G41: =RANK(F41,F$5:F$42,0) -> 37 | H41: =C41 -> 0.2 | I41: =D41 -> 0.74468085 | J41: =E41 -> 0.54795391 | K41: =ROUND(Notes!$B$4*I41+Notes!$B$5*H41+Notes!$B$6*J41,4) -> 0.4911 | L41: =RANK(K41,K$5:K$42,0) -> 37
...

Sheet 2029
A1: Net Present Value of Capital Allowances, OECD Ranking 2029: current law vs. Canada immediate-expensing reform
A2: Weighted avg = weights (Notes) applied to asset NPVs (source: final-data/npv_all_years.csv). Reform sets Canada machinery and buildings to 1.0; intangibles unchanged. Ranks: RANK on weighted avg rounded to 4 dp, ties=min.
A4: Country | B4: ISO | C4: Buildings (current law) | D4: Machinery (current law) | E4: Intangibles (current law) | F4: Weighted avg (current law) | G4: Rank (current law) | H4: Buildings (reform) | I4: Machinery (reform) | J4: Intangibles (reform) | K4: Weighted avg (reform) | L4: Rank (reform)
A5: Estonia | B5: EST | C5: =1 -> 1 | D5: =1 -> 1 | E5: =1 -> 1 | F5: =ROUND(Notes!$B$4*D5+Notes!$B$5*C5+Notes!$B$6*E5,4) -> 1 | G5: =RANK(F5,F$5:F$42,0) -> 1 | H5: =C5 -> 1 | I5: =D5 -> 1 | J5: =E5 -> 1 | K5: =ROUND(Notes!$B$4*I5+Notes!$B$5*H5+Notes!$B$6*J5,4) -> 1 | L5: =RANK(K5,K$5:K$42,0) -> 1
A6: Latvia | B6: LVA | C6: =1 -> 1 | D6: =1 -> 1 | E6: =1 -> 1 | F6: =ROUND(Notes!$B$4*D6+Notes!$B$5*C6+Notes!$B$6*E6,4) -> 1 | G6: =RANK(F6,F$5:F$42,0) -> 1 | H6: =C6 -> 1 | I6: =D6 -> 1 | J6: =E6 -> 1 | K6: =ROUND(Notes!$B$4*I6+Notes!$B$5*H6+Notes!$B$6*J6,4) -> 1 | L6: =RANK(K6,K$5:K$42,0) -> 1
A7: United States | B7: USA | C7: =0.34958311169213 -> 0.34958311 | D7: =1 -> 1 | E7: =0.632751338890881 -> 0.63275134 | F7: =ROUND(Notes!$B$4*D7+Notes!$B$5*C7+Notes!$B$6*E7,4) -> 0.6774 | G7: =RANK(F7,F$5:F$42,0) -> 20 | H7: =C7 -> 0.34958311 | I7: =D7 -> 1 | J7: =E7 -> 0.63275134 | K7: =ROUND(Notes!$B$4*I7+Notes!$B$5*H7+Notes!$B$6*J7,4) -> 0.6774 | L7: =RANK(K7,K$5:K$42,0) -> 20
A8: Lithuania | B8: LTU | C8: =0.826923076923077 -> 0.82692308 | D8: =1 -> 1 | E8: =1 -> 1 | F8: =ROUND(Notes!$B$4*D8+Notes!$B$5*C8+Notes!$B$6*E8,4) -> 0.9288 | G8: =RANK(F8,F$5:F$42,0) -> 3 | H8: =C8 -> 0.82692308 | I8: =D8 -> 1 | J8: =E8 -> 1 | K8: =ROUND(Notes!$B$4*I8+Notes!$B$5*H8+Notes!$B$6*J8,4) -> 0.9288 | L8: =RANK(K8,K$5:K$42,0) -> 3
A9: Canada | B9: CAN | C9: =0.635714285714286 -> 0.63571429 | D9: =1 -> 1 | E9: =0.43 -> 0.43 | F9: =ROUND(Notes!$B$4*D9+Notes!$B$5*C9+Notes!$B$6*E9,4) -> 0.765 | G9: =RANK(F9,F$5:F$42,0) -> 4 | H9: =1 -> 1 | I9: =1 -> 1 | J9: =E9 -> 0.43 | K9: =ROUND(Notes!$B$4*I9+Notes!$B$5*H9+Notes!$B$6*J9,4) -> 0.9149 | L9: =RANK(K9,K$5:K$42,0) -> 4
A10: Italy | B10: ITA | C10: =0.576669379707147 -> 0.57666938 | D10: =0.869865253929667 -> 0.86986525 | E10: =0.965116279069767 -> 0.96511628 | F10: =ROUND(Notes!$B$4*D10+Notes!$B$5*C10+Notes!$B$6*E10,4) -> 0.7634 | G10: =RANK(F10,F$5:F$42,0) -> 5 | H10: =C10 -> 0.57666938 | I10: =D10 -> 0.86986525 | J10: =E10 -> 0.96511628 | K10: =ROUND(Notes!$B$4*I10+Notes!$B$5*H10+Notes!$B$6*J10,4) -> 0.7634 | L10: =RANK(K10,K$5:K$42,0) -> 5
A11: Korea | B11: KOR | C11: =0.547953910556565 -> 0.54795391 | D11: =0.921720532319392 -> 0.92172053 | E11: =0.813463195231154 -> 0.8134632 | F11: =ROUND(Notes!$B$4*D11+Notes!$B$5*C11+Notes!$B$6*E11,4) -> 0.7517 | G11: =RANK(F11,F$5:F$42,0) -> 6 | H11: =C11 -> 0.54795391 | I11: =D11 -> 0.92172053 | J11: =E11 -> 0.8134632 | K11: =ROUND(Notes!$B$4*I11+Notes!$B$5*H11+Notes!$B$6*J11,4) -> 0.7517 | L11: =RANK(K11,K$5:K$42,0) -> 6
A12: Iceland | B12: ISL | C12: =0.602353618717047 -> 0.60235362 | D12: =0.86 -> 0.86 | E12: =0.812269350072009 -> 0.81226935 | F12: =ROUND(Notes!$B$4*D12+Notes!$B$5*C12+Notes!$B$6*E12,4) -> 0.7468 | G12: =RANK(F12,F$5:F$42,0) -> 7 | H12: =C12 -> 0.60235362 | I12: =D12 -> 0.86 | J12: =E12 -> 0.81226935 | K12: =ROUND(Notes!$B$4*I12+Notes!$B$5*H12+Notes!$B$6*J12,4) -> 0.7468 | L12: =RANK(K12,K$5:K$42,0) -> 7
A13: France | B13: FRA | C13: =0.547953910556565 -> 0.54795391 | D13: =0.880275603755891 -> 0.8802756 | E13: =0.869865253929667 -> 0.86986525 | F13: =ROUND(Notes!$B$4*D13+Notes!$B$5*C13+Notes!$B$6*E13,4) -> 0.7419 | G13: =RANK(F13,F$5:F$42,0) -> 8 | H13: =C13 -> 0.54795391 | I13: =D13 -> 0.8802756 | J13: =E13 -> 0.86986525 | K13: =ROUND(Notes!$B$4*I13+Notes!$B$5*H13+Notes!$B$6*J13,4) -> 0.7419 | L13: =RANK(K13,K$5:K$42,0) -> 8
A14: Switzerland | B14: CHE | C14: =0.554838709677419 -> 0.55483871 | D14: =0.86 -> 0.86 | E14: =0.905263157894737 -> 0.90526316 | F14: =ROUND(Notes!$B$4*D14+Notes!$B$5*C14+Notes!$B$6*E14,4) -> 0.7411 | G14: =RANK(F14,F$5:F$42,0) -> 9 | H14: =C14 -> 0.55483871 | I14: =D14 -> 0.86 | J14: =E14 -> 0.90526316 | K14: =ROUND(Notes!$B$4*I14+Notes!$B$5*H14+Notes!$B$6*J14,4) -> 0.7411 | L14: =RANK(K14,K$5:K$42,0) -> 9
A15: Slovakia | B15: SVK | C15: =0.547953910556565 -> 0.54795391 | D15: =0.873879108036537 -> 0.87387911 | E15: =0.869865253929667 -> 0.86986525 | F15: =ROUND(Notes!$B$4*D15+Notes!$B$5*C15+Notes!$B$6*E15,4) -> 0.7391 | G15: =RANK(F15,F$5:F$42,0) -> 10 | H15: =C15 -> 0.54795391 | I15: =D15 -> 0.87387911 | J15: =E15 -> 0.86986525 | K15: =ROUND(Notes!$B$4*I15+Notes!$B$5*H15+Notes!$B$6*J15,4) -> 0.7391 | L15: =RANK(K15,K$5:K$42,0) -> 10
A16: Belgium | B16: BEL | C16: =0.547953910556565 -> 0.54795391 | D16: =0.869865253929667 -> 0.86986525 | E16: =0.869865253929667 -> 0.86986525 | F16: =ROUND(Notes!$B$4*D16+Notes!$B$5*C16+Notes!$B$6*E16,4) -> 0.7373 | G16: =RANK(F16,F$5:F$42,0) -> 11 | H16: =C16 -> 0.54795391 | I16: =D16 -> 0.86986525 | J16: =E16 -> 0.86986525 | K16: =ROUND(Notes!$B$4*I16+Notes!$B$5*H16+Notes!$B$6*J16,4) -> 0.7373 | L16: =RANK(K16,K$5:K$42,0) -> 11
A17: Czech Republic | B17: CZE | C17: =0.543222830616488 -> 0.54322283 | D17: =0.873879108036537 -> 0.87387911 | E17: =0.841318847888109 -> 0.84131885 | F17: =ROUND(Notes!$B$4*D17+Notes!$B$5*C17+Notes!$B$6*E17,4) -> 0.7329 | G17: =RANK(F17,F$5:F$42,0) -> 12 | H17: =C17 -> 0.54322283 | I17: =D17 -> 0.87387911 | J17: =E17 -> 0.84131885 | K17: =ROUND(Notes!$B$4*I17+Notes!$B$5*H17+Notes!$B$6*J17,4) -> 0.7329 | L17: =RANK(K17,K$5:K$42,0) -> 12
A18: Mexico | B18: MEX | C18: =0.630382676079967 -> 0.63038268 | D18: =0.795219524916135 -> 0.79521952 | E18: =0.795219524916135 -> 0.79521952 | F18: =ROUND(Notes!$B$4*D18+Notes!$B$5*C18+Notes!$B$6*E18,4) -> 0.7274 | G18: =RANK(F18,F$5:F$42,0) -> 13 | H18: =C18 -> 0.63038268 | I18: =D18 -> 0.79521952 | J18: =E18 -> 0.79521952 | K18: =ROUND(Notes!$B$4*I18+Notes!$B$5*H18+Notes!$B$6*J18,4) -> 0.7274 | L18: =RANK(K18,K$5:K$42,0) -> 13
A19: United Kingdom | B19: GBR | C19: =0.391406012913837 -> 0.39140601 | D19: =1 -> 1 | E19: =0.826923076923077 -> 0.82692308 | F19: =ROUND(Notes!$B$4*D19+Notes!$B$5*C19+Notes!$B$6*E19,4) -> 0.7236 | G19: =RANK(F19,F$5:F$42,0) -> 14 | H19: =C19 -> 0.39140601 | I19: =D19 -> 1 | J19: =E19 -> 0.82692308 | K19: =ROUND(Notes!$B$4*I19+Notes!$B$5*H19+Notes!$B$6*J19,4) -> 0.7236 | L19: =RANK(K19,K$5:K$42,0) -> 14
A20: Israel | B20: ISR | C20: =0.478865241362287 -> 0.47886524 | D20: =0.901030024355631 -> 0.90103002 | E20: =0.835370889649727 -> 0.83537089 | F20: =ROUND(Notes!$B$4*D20+Notes!$B$5*C20+Notes!$B$6*E20,4) -> 0.7174 | G20: =RANK(F20,F$5:F$42,0) -> 15 | H20: =C20 -> 0.47886524 | I20: =D20 -> 0.90103002 | J20: =E20 -> 0.83537089 | K20: =ROUND(Notes!$B$4*I20+Notes!$B$5*H20+Notes!$B$6*J20,4) -> 0.7174 | L20: =RANK(K20,K$5:K$42,0) -> 15
A21: Luxembourg | B21: LUX | C21: =0.479318672008477 -> 0.47931867 | D21: =0.873417350634541 -> 0.87341735 | E21: =0.869865253929667 -> 0.86986525 | F21: =ROUND(Notes!$B$4*D21+Notes!$B$5*C21+Notes!$B$6*E21,4) -> 0.7107 | G21: =RANK(F21,F$5:F$42,0) -> 16 | H21: =C21 -> 0.47931867 | I21: =D21 -> 0.87341735 | J21: =E21 -> 0.86986525 | K21: =ROUND(Notes!$B$4*I21+Notes!$B$5*H21+Notes!$B$6*J21,4) -> 0.7107 | L21: =RANK(K21,K$5:K$42,0) -> 16
A22: Sweden | B22: SWE | C22: =0.479318672008477 -> 0.47931867 | D22: =0.86 -> 0.86 | E22: =0.86 -> 0.86 | F22: =ROUND(Notes!$B$4*D22+Notes!$B$5*C22+Notes!$B$6*E22,4) -> 0.7033 | G22: =RANK(F22,F$5:F$42,0) -> 17 | H22: =C22 -> 0.47931867 | I22: =D22 -> 0.86 | J22: =E22 -> 0.86 | K22: =ROUND(Notes!$B$4*I22+Notes!$B$5*H22+Notes!$B$6*J22,4) -> 0.7033 | L22: =RANK(K22,K$5:K$42,0) -> 17
A23: Portugal | B23: PRT | C23: =0.547953910556565 -> 0.54795391 | D23: =0.888411247396436 -> 0.88841125 | E23: =0.547953910556565 -> 0.54795391 | F23: =ROUND(Notes!$B$4*D23+Notes!$B$5*C23+Notes!$B$6*E23,4) -> 0.6975 | G23: =RANK(F23,F$5:F$42,0) -> 18 | H23: =C23 -> 0.54795391 | I23: =D23 -> 0.88841125 | J23: =E23 -> 0.54795391 | K23: =ROUND(Notes!$B$4*I23+Notes!$B$5*H23+Notes!$B$6*J23,4) -> 0.6975 | L23: =RANK(K23,K$5:K$42,0) -> 18
A24: Finland | B24: FIN | C24: =0.518965517241379 -> 0.51896552 | D24: =0.826923076923077 -> 0.82692308 | E24: =0.737888702767901 -> 0.7378887 | F24: =ROUND(Notes!$B$4*D24+Notes!$B$5*C24+Notes!$B$6*E24,4) -> 0.6869 | G24: =RANK(F24,F$5:F$42,0) -> 19 | H24: =C24 -> 0.51896552 | I24: =D24 -> 0.82692308 | J24: =E24 -> 0.7378887 | K24: =ROUND(Notes!$B$4*I24+Notes!$B$5*H24+Notes!$B$6*J24,4) -> 0.6869 | L24: =RANK(K24,K$5:K$42,0) -> 19
A25: Germany | B25: DEU | C25: =0.391406012913837 -> 0.39140601 | D25: =0.737888702767901 -> 0.7378887 | E25: =0.869865253929667 -> 0.86986525 | F25: =ROUND(Notes!$B$4*D25+Notes!$B$5*C25+Notes!$B$6*E25,4) -> 0.6149 | G25: =RANK(F25,F$5:F$42,0) -> 29 | H25: =C25 -> 0.39140601 | I25: =D25 -> 0.7378887 | J25: =E25 -> 0.86986525 | K25: =ROUND(Notes!$B$4*I25+Notes!$B$5*H25+Notes!$B$6*J25,4) -> 0.6149 | L25: =RANK(K25,K$5:K$42,0) -> 29
A26: Austria | B26: AUT | C26: =0.408845614108812 -> 0.40884561 | D26: =0.884365027341364 -> 0.88436503 | E26: =0.737888702767901 -> 0.7378887 | F26: =ROUND(Notes!$B$4*D26+Notes!$B$5*C26+Notes!$B$6*E26,4) -> 0.6668 | G26: =RANK(F26,F$5:F$42,0) -> 21 | H26: =C26 -> 0.40884561 | I26: =D26 -> 0.88436503 | J26: =E26 -> 0.7378887 | K26: =ROUND(Notes!$B$4*I26+Notes!$B$5*H26+Notes!$B$6*J26,4) -> 0.6668 | L26: =RANK(K26,K$5:K$42,0) -> 21
A27: Turkey | B27: TUR | C27: =0.431068736527055 -> 0.43106874 | D27: =0.864149148541634 -> 0.86414915 | E27: =0.69441435606903 -> 0.69441436 | F27: =ROUND(Notes!$B$4*D27+Notes!$B$5*C27+Notes!$B$6*E27,4) -> 0.6605 | G27: =RANK(F27,F$5:F$42,0) -> 22 | H27: =C27 -> 0.43106874 | I27: =D27 -> 0.86414915 | J27: =E27 -> 0.69441436 | K27: =ROUND(Notes!$B$4*I27+Notes!$B$5*H27+Notes!$B$6*J27,4) -> 0.6605 | L27: =RANK(K27,K$5:K$42,0) -> 22
A28: Slovenia | B28: SVN | C28: =0.391406012913837 -> 0.39140601 | D28: =0.869865253929667 -> 0.86986525 | E28: =0.737888702767901 -> 0.7378887 | F28: =ROUND(Notes!$B$4*D28+Notes!$B$5*C28+Notes!$B$6*E28,4) -> 0.6532 | G28: =RANK(F28,F$5:F$42,0) -> 23 | H28: =C28 -> 0.39140601 | I28: =D28 -> 0.86986525 | J28: =E28 -> 0.7378887 | K28: =ROUND(Notes!$B$4*I28+Notes!$B$5*H28+Notes!$B$6*J28,4) -> 0.6532 | L28: =RANK(K28,K$5:K$42,0) -> 23
